[2025-04-20 09:29:44,458: INFO: main: wlcm to custm log]
[2025-04-20 09:44:09,100: INFO: main: wlcm to custm log]
[2025-04-20 09:46:46,950: INFO: main: wlcm to custm log]
[2025-04-20 09:53:58,110: INFO: main: wlcm to custm log]
[2025-04-20 10:14:53,056: INFO: main: wlcm to custm log]
[2025-04-20 10:16:14,258: INFO: main: wlcm to custm log]
[2025-04-20 10:16:23,272: INFO: main: wlcm to custm log]
[2025-04-24 23:43:46,133: INFO: common: yaml file: config\config.yaml loaded successfully]
[2025-04-24 23:46:48,716: INFO: common: yaml file: config\config.yaml loaded successfully]
[2025-04-24 23:46:48,724: INFO: common: yaml file: params.yaml loaded successfully]
[2025-04-24 23:46:48,726: INFO: common: created directory at: artifacts]
[2025-04-24 23:46:48,729: INFO: common: created directory at: artifacts/data_ingestion]
[2025-04-24 23:47:00,798: INFO: common: yaml file: config\config.yaml loaded successfully]
[2025-04-24 23:47:00,800: INFO: common: yaml file: params.yaml loaded successfully]
[2025-04-24 23:47:00,802: INFO: common: created directory at: artifacts]
[2025-04-24 23:47:00,803: INFO: common: created directory at: artifacts/data_ingestion]
[2025-04-24 23:47:06,652: INFO: common: yaml file: config\config.yaml loaded successfully]
[2025-04-24 23:47:06,654: INFO: common: yaml file: params.yaml loaded successfully]
[2025-04-24 23:47:06,655: INFO: common: created directory at: artifacts]
[2025-04-24 23:47:06,656: INFO: common: created directory at: artifacts/data_ingestion]
[2025-04-29 21:34:31,897: INFO: main: >>>>>>>> stage DAta Ingestion Stage started here <<<<<<<<]
[2025-04-29 21:34:31,899: INFO: common: yaml file: config\config.yaml loaded successfully]
[2025-04-29 21:34:31,901: INFO: common: yaml file: params.yaml loaded successfully]
[2025-04-29 21:34:31,902: INFO: common: created directory at: artifacts]
[2025-04-29 21:34:31,903: INFO: common: created directory at: artifacts/data_ingestion]
[2025-04-29 21:34:31,904: INFO: data_ingestion: Downloading data from https://drive.google.com/file/d/1zsI3e2QVpuhM1hjHMlr-8lx6os6X2UQF/view?usp=sharing into file artifacts/data_ingestion/data.zip]
[2025-04-29 21:36:20,879: INFO: data_ingestion: Downloaded data from https://drive.google.com/file/d/1zsI3e2QVpuhM1hjHMlr-8lx6os6X2UQF/view?usp=sharing into file artifacts/data_ingestion/data.zip]
[2025-04-29 21:36:40,540: INFO: main: >>>>>>>>> stage DAta Ingestion Stage completed <<<<<<<<<

X=======================================================X]
[2025-05-01 15:16:40,027: INFO: main: >>>>>>>> stage Data Ingestion Stage started here <<<<<<<<]
[2025-05-01 15:16:40,042: INFO: common: yaml file: config\config.yaml loaded successfully]
[2025-05-01 15:16:40,044: INFO: common: yaml file: params.yaml loaded successfully]
[2025-05-01 15:16:40,051: INFO: common: created directory at: artifacts]
[2025-05-01 15:16:40,051: INFO: common: created directory at: artifacts/data_ingestion]
[2025-05-01 15:16:40,052: INFO: data_ingestion: Downloading data from https://drive.google.com/file/d/1zsI3e2QVpuhM1hjHMlr-8lx6os6X2UQF/view?usp=sharing into file artifacts/data_ingestion/data.zip]
[2025-05-01 15:19:51,362: INFO: data_ingestion: Downloaded data from https://drive.google.com/file/d/1zsI3e2QVpuhM1hjHMlr-8lx6os6X2UQF/view?usp=sharing into file artifacts/data_ingestion/data.zip]
[2025-05-01 15:20:06,367: INFO: main: >>>>>>>>> stage Data Ingestion Stage completed <<<<<<<<<

X=======================================================X]
[2025-05-01 16:32:49,808: INFO: common: yaml file: config\config.yaml loaded successfully]
[2025-05-01 16:32:49,824: INFO: common: yaml file: params.yaml loaded successfully]
[2025-05-01 16:32:49,826: INFO: common: created directory at: artifacts]
[2025-05-01 16:34:22,321: INFO: common: yaml file: config\config.yaml loaded successfully]
[2025-05-01 16:34:22,324: INFO: common: yaml file: params.yaml loaded successfully]
[2025-05-01 16:34:22,325: INFO: common: created directory at: artifacts]
[2025-05-01 16:34:22,327: INFO: common: created directory at: artifacts/prepare_base_model]
[2025-05-01 16:34:32,781: WARNING: saving_utils: Compiled the loaded model, but the compiled metrics have yet to be built. `model.compile_metrics` will be empty until you train or evaluate the model.]
[2025-05-01 16:38:59,992: INFO: common: yaml file: config\config.yaml loaded successfully]
[2025-05-01 16:38:59,996: INFO: common: yaml file: params.yaml loaded successfully]
[2025-05-01 16:38:59,998: INFO: common: created directory at: artifacts]
[2025-05-01 16:38:59,999: INFO: common: created directory at: artifacts/prepare_base_model]
[2025-05-01 16:39:00,406: WARNING: saving_utils: Compiled the loaded model, but the compiled metrics have yet to be built. `model.compile_metrics` will be empty until you train or evaluate the model.]
[2025-05-01 16:40:52,656: INFO: common: yaml file: config\config.yaml loaded successfully]
[2025-05-01 16:40:52,658: INFO: common: yaml file: params.yaml loaded successfully]
[2025-05-01 16:40:52,659: INFO: common: created directory at: artifacts]
[2025-05-01 16:40:52,660: INFO: common: created directory at: artifacts/prepare_base_model]
[2025-05-01 16:40:53,083: WARNING: saving_utils: Compiled the loaded model, but the compiled metrics have yet to be built. `model.compile_metrics` will be empty until you train or evaluate the model.]
[2025-05-01 16:45:42,153: INFO: common: yaml file: config\config.yaml loaded successfully]
[2025-05-01 16:45:42,155: INFO: common: yaml file: params.yaml loaded successfully]
[2025-05-01 16:45:42,156: INFO: common: created directory at: artifacts]
[2025-05-01 16:45:42,158: INFO: common: created directory at: artifacts/prepare_base_model]
[2025-05-01 16:45:42,624: WARNING: saving_utils: Compiled the loaded model, but the compiled metrics have yet to be built. `model.compile_metrics` will be empty until you train or evaluate the model.]
[2025-05-01 16:45:57,857: INFO: common: yaml file: config\config.yaml loaded successfully]
[2025-05-01 16:45:57,861: INFO: common: yaml file: params.yaml loaded successfully]
[2025-05-01 16:45:57,862: INFO: common: created directory at: artifacts]
[2025-05-01 16:45:57,863: INFO: common: created directory at: artifacts/prepare_base_model]
[2025-05-01 16:45:58,162: WARNING: saving_utils: Compiled the loaded model, but the compiled metrics have yet to be built. `model.compile_metrics` will be empty until you train or evaluate the model.]
[2025-05-01 17:09:12,808: INFO: main: >>>>>>>> stage Data Ingestion Stage started here <<<<<<<<]
[2025-05-01 17:09:12,811: INFO: common: yaml file: config\config.yaml loaded successfully]
[2025-05-01 17:09:12,812: INFO: common: yaml file: params.yaml loaded successfully]
[2025-05-01 17:09:12,812: INFO: common: created directory at: artifacts]
[2025-05-01 17:09:12,813: INFO: common: created directory at: artifacts/data_ingestion]
[2025-05-01 17:09:12,813: INFO: data_ingestion: Downloading data from https://drive.google.com/file/d/1zsI3e2QVpuhM1hjHMlr-8lx6os6X2UQF/view?usp=sharing into file artifacts/data_ingestion/data.zip]
[2025-05-01 17:12:29,730: INFO: data_ingestion: Downloaded data from https://drive.google.com/file/d/1zsI3e2QVpuhM1hjHMlr-8lx6os6X2UQF/view?usp=sharing into file artifacts/data_ingestion/data.zip]
[2025-05-01 17:12:49,391: INFO: main: >>>>>>>>> stage Data Ingestion Stage completed <<<<<<<<<

X=======================================================X]
[2025-05-01 17:12:49,391: INFO: main: >>>>>>>>>>>>>> Stage Model Preparation started <<<<<<<<<<<<<<]
[2025-05-01 17:12:49,391: INFO: common: yaml file: config\config.yaml loaded successfully]
[2025-05-01 17:12:49,391: INFO: common: yaml file: params.yaml loaded successfully]
[2025-05-01 17:12:49,391: INFO: common: created directory at: artifacts]
[2025-05-01 17:12:49,391: INFO: common: created directory at: artifacts/prepare_base_model]
[2025-05-01 17:12:51,803: WARNING: saving_utils: Compiled the loaded model, but the compiled metrics have yet to be built. `model.compile_metrics` will be empty until you train or evaluate the model.]
[2025-05-01 17:12:52,130: INFO: main: >>>>>>>>>>>> Stage Model Preparation COMPLETED <<<<<<<<<

X=========================================================X]
[2025-05-03 16:50:26,088: INFO: common: yaml file: config\config.yaml loaded successfully]
[2025-05-03 16:50:26,106: INFO: common: yaml file: params.yaml loaded successfully]
[2025-05-03 16:50:26,107: INFO: common: created directory at: artifacts]
[2025-05-03 16:51:32,045: INFO: common: yaml file: config\config.yaml loaded successfully]
[2025-05-03 16:51:32,046: INFO: common: yaml file: params.yaml loaded successfully]
[2025-05-03 16:51:32,047: INFO: common: created directory at: artifacts]
[2025-05-03 16:52:09,204: INFO: common: yaml file: config\config.yaml loaded successfully]
[2025-05-03 16:52:09,204: INFO: common: yaml file: params.yaml loaded successfully]
[2025-05-03 16:52:09,204: INFO: common: created directory at: artifacts]
[2025-05-03 16:53:06,425: INFO: stage_03_model_training: >>>>>>>> stage Model Training Stage started here <<<<<<<<]
[2025-05-03 16:53:06,425: ERROR: stage_03_model_training: Training.__init__() missing 1 required positional argument: 'config']
Traceback (most recent call last):
  File "d:\E2E Proj\src\cnnClassifier\pipeline\stage_03_model_training.py", line 26, in <module>
    obj = Training()
TypeError: Training.__init__() missing 1 required positional argument: 'config'
[2025-05-03 16:55:16,396: INFO: stage_03_model_training: >>>>>>>> stage Model Training Stage started here <<<<<<<<]
[2025-05-03 16:55:16,396: INFO: common: yaml file: config\config.yaml loaded successfully]
[2025-05-03 16:55:16,396: INFO: common: yaml file: params.yaml loaded successfully]
[2025-05-03 16:55:16,396: INFO: common: created directory at: artifacts]
[2025-05-03 16:55:16,396: INFO: common: created directory at: artifacts\trainig]
[2025-05-03 16:55:16,396: ERROR: stage_03_model_training: TrainingConfig.__init__() missing 1 required positional argument: 'training_data']
Traceback (most recent call last):
  File "d:\E2E Proj\src\cnnClassifier\pipeline\stage_03_model_training.py", line 27, in <module>
    obj.main()
  File "d:\E2E Proj\src\cnnClassifier\pipeline\stage_03_model_training.py", line 15, in main
    training_config = config.get_training_config()
  File "d:\e2e proj\src\cnnClassifier\config\configuration.py", line 72, in get_training_config
    training_config = TrainingConfig(
TypeError: TrainingConfig.__init__() missing 1 required positional argument: 'training_data'
[2025-05-03 16:55:32,485: INFO: main: >>>>>>>> stage Data Ingestion Stage started here <<<<<<<<]
[2025-05-03 16:55:32,485: INFO: common: yaml file: config\config.yaml loaded successfully]
[2025-05-03 16:55:32,485: INFO: common: yaml file: params.yaml loaded successfully]
[2025-05-03 16:55:32,485: INFO: common: created directory at: artifacts]
[2025-05-03 16:55:32,485: INFO: common: created directory at: artifacts/data_ingestion]
[2025-05-03 16:55:32,485: INFO: data_ingestion: Downloading data from https://drive.google.com/file/d/1zsI3e2QVpuhM1hjHMlr-8lx6os6X2UQF/view?usp=sharing into file artifacts/data_ingestion/data.zip]
[2025-05-03 17:10:52,570: ERROR: main: ('Connection broken: IncompleteRead(498396667 bytes read, 1129522641 more expected)', IncompleteRead(498396667 bytes read, 1129522641 more expected))]
Traceback (most recent call last):
  File "C:\Users\Gourav\AppData\Local\Programs\Python\Python310\lib\site-packages\urllib3\response.py", line 754, in _error_catcher
    yield
  File "C:\Users\Gourav\AppData\Local\Programs\Python\Python310\lib\site-packages\urllib3\response.py", line 900, in _raw_read
    raise IncompleteRead(self._fp_bytes_read, self.length_remaining)
urllib3.exceptions.IncompleteRead: IncompleteRead(498396667 bytes read, 1129522641 more expected)

The above exception was the direct cause of the following exception:

Traceback (most recent call last):
  File "C:\Users\Gourav\AppData\Local\Programs\Python\Python310\lib\site-packages\requests\models.py", line 820, in generate
    yield from self.raw.stream(chunk_size, decode_content=True)
  File "C:\Users\Gourav\AppData\Local\Programs\Python\Python310\lib\site-packages\urllib3\response.py", line 1066, in stream
    data = self.read(amt=amt, decode_content=decode_content)
  File "C:\Users\Gourav\AppData\Local\Programs\Python\Python310\lib\site-packages\urllib3\response.py", line 983, in read
    data = self._raw_read(amt)
  File "C:\Users\Gourav\AppData\Local\Programs\Python\Python310\lib\site-packages\urllib3\response.py", line 878, in _raw_read
    with self._error_catcher():
  File "C:\Users\Gourav\AppData\Local\Programs\Python\Python310\lib\contextlib.py", line 153, in __exit__
    self.gen.throw(typ, value, traceback)
  File "C:\Users\Gourav\AppData\Local\Programs\Python\Python310\lib\site-packages\urllib3\response.py", line 778, in _error_catcher
    raise ProtocolError(arg, e) from e
urllib3.exceptions.ProtocolError: ('Connection broken: IncompleteRead(498396667 bytes read, 1129522641 more expected)', IncompleteRead(498396667 bytes read, 1129522641 more expected))

During handling of the above exception, another exception occurred:

Traceback (most recent call last):
  File "d:\E2E Proj\main.py", line 13, in <module>
    obj.main()
  File "d:\e2e proj\src\cnnClassifier\pipeline\stage_01_data_ingestion.py", line 15, in main
    data_ingestion.download_file()
  File "d:\e2e proj\src\cnnClassifier\components\data_ingestion.py", line 31, in download_file
    raise e
  File "d:\e2e proj\src\cnnClassifier\components\data_ingestion.py", line 26, in download_file
    gdown.download(prefix+file_id, zip_download_dir)
  File "C:\Users\Gourav\AppData\Local\Programs\Python\Python310\lib\site-packages\gdown\download.py", line 368, in download
    for chunk in res.iter_content(chunk_size=CHUNK_SIZE):
  File "C:\Users\Gourav\AppData\Local\Programs\Python\Python310\lib\site-packages\requests\models.py", line 822, in generate
    raise ChunkedEncodingError(e)
requests.exceptions.ChunkedEncodingError: ('Connection broken: IncompleteRead(498396667 bytes read, 1129522641 more expected)', IncompleteRead(498396667 bytes read, 1129522641 more expected))
[2025-05-03 17:11:27,048: INFO: main: >>>>>>>> stage Data Ingestion Stage started here <<<<<<<<]
[2025-05-03 17:11:27,050: INFO: common: yaml file: config\config.yaml loaded successfully]
[2025-05-03 17:11:27,052: INFO: common: yaml file: params.yaml loaded successfully]
[2025-05-03 17:11:27,052: INFO: common: created directory at: artifacts]
[2025-05-03 17:11:27,052: INFO: common: created directory at: artifacts/data_ingestion]
[2025-05-03 17:11:27,053: INFO: data_ingestion: Downloading data from https://drive.google.com/file/d/1zsI3e2QVpuhM1hjHMlr-8lx6os6X2UQF/view?usp=sharing into file artifacts/data_ingestion/data.zip]
[2025-05-03 17:13:21,673: INFO: main: >>>>>>>> stage Data Ingestion Stage started here <<<<<<<<]
[2025-05-03 17:13:21,673: INFO: common: yaml file: config\config.yaml loaded successfully]
[2025-05-03 17:13:21,673: INFO: common: yaml file: params.yaml loaded successfully]
[2025-05-03 17:13:21,673: INFO: common: created directory at: artifacts]
[2025-05-03 17:13:21,673: INFO: common: created directory at: artifacts/data_ingestion]
[2025-05-03 17:13:21,673: INFO: data_ingestion: Downloading data from https://drive.google.com/file/d/1zsI3e2QVpuhM1hjHMlr-8lx6os6X2UQF/view?usp=sharing into file artifacts/data_ingestion/data.zip]
[2025-05-03 17:16:10,140: ERROR: main: ('Connection aborted.', ConnectionAbortedError(10053, 'An established connection was aborted by the software in your host machine', None, 10053, None))]
Traceback (most recent call last):
  File "C:\Users\Gourav\AppData\Local\Programs\Python\Python310\lib\site-packages\urllib3\connectionpool.py", line 787, in urlopen
    response = self._make_request(
  File "C:\Users\Gourav\AppData\Local\Programs\Python\Python310\lib\site-packages\urllib3\connectionpool.py", line 488, in _make_request
    raise new_e
  File "C:\Users\Gourav\AppData\Local\Programs\Python\Python310\lib\site-packages\urllib3\connectionpool.py", line 464, in _make_request
    self._validate_conn(conn)
  File "C:\Users\Gourav\AppData\Local\Programs\Python\Python310\lib\site-packages\urllib3\connectionpool.py", line 1093, in _validate_conn
    conn.connect()
  File "C:\Users\Gourav\AppData\Local\Programs\Python\Python310\lib\site-packages\urllib3\connection.py", line 741, in connect
    sock_and_verified = _ssl_wrap_socket_and_match_hostname(
  File "C:\Users\Gourav\AppData\Local\Programs\Python\Python310\lib\site-packages\urllib3\connection.py", line 920, in _ssl_wrap_socket_and_match_hostname
    ssl_sock = ssl_wrap_socket(
  File "C:\Users\Gourav\AppData\Local\Programs\Python\Python310\lib\site-packages\urllib3\util\ssl_.py", line 480, in ssl_wrap_socket
    ssl_sock = _ssl_wrap_socket_impl(sock, context, tls_in_tls, server_hostname)
  File "C:\Users\Gourav\AppData\Local\Programs\Python\Python310\lib\site-packages\urllib3\util\ssl_.py", line 524, in _ssl_wrap_socket_impl
    return ssl_context.wrap_socket(sock, server_hostname=server_hostname)
  File "C:\Users\Gourav\AppData\Local\Programs\Python\Python310\lib\ssl.py", line 513, in wrap_socket
    return self.sslsocket_class._create(
  File "C:\Users\Gourav\AppData\Local\Programs\Python\Python310\lib\ssl.py", line 1071, in _create
    self.do_handshake()
  File "C:\Users\Gourav\AppData\Local\Programs\Python\Python310\lib\ssl.py", line 1342, in do_handshake
    self._sslobj.do_handshake()
ConnectionAbortedError: [WinError 10053] An established connection was aborted by the software in your host machine

During handling of the above exception, another exception occurred:

Traceback (most recent call last):
  File "C:\Users\Gourav\AppData\Local\Programs\Python\Python310\lib\site-packages\requests\adapters.py", line 667, in send
    resp = conn.urlopen(
  File "C:\Users\Gourav\AppData\Local\Programs\Python\Python310\lib\site-packages\urllib3\connectionpool.py", line 841, in urlopen
    retries = retries.increment(
  File "C:\Users\Gourav\AppData\Local\Programs\Python\Python310\lib\site-packages\urllib3\util\retry.py", line 474, in increment
    raise reraise(type(error), error, _stacktrace)
  File "C:\Users\Gourav\AppData\Local\Programs\Python\Python310\lib\site-packages\urllib3\util\util.py", line 38, in reraise
    raise value.with_traceback(tb)
  File "C:\Users\Gourav\AppData\Local\Programs\Python\Python310\lib\site-packages\urllib3\connectionpool.py", line 787, in urlopen
    response = self._make_request(
  File "C:\Users\Gourav\AppData\Local\Programs\Python\Python310\lib\site-packages\urllib3\connectionpool.py", line 488, in _make_request
    raise new_e
  File "C:\Users\Gourav\AppData\Local\Programs\Python\Python310\lib\site-packages\urllib3\connectionpool.py", line 464, in _make_request
    self._validate_conn(conn)
  File "C:\Users\Gourav\AppData\Local\Programs\Python\Python310\lib\site-packages\urllib3\connectionpool.py", line 1093, in _validate_conn
    conn.connect()
  File "C:\Users\Gourav\AppData\Local\Programs\Python\Python310\lib\site-packages\urllib3\connection.py", line 741, in connect
    sock_and_verified = _ssl_wrap_socket_and_match_hostname(
  File "C:\Users\Gourav\AppData\Local\Programs\Python\Python310\lib\site-packages\urllib3\connection.py", line 920, in _ssl_wrap_socket_and_match_hostname
    ssl_sock = ssl_wrap_socket(
  File "C:\Users\Gourav\AppData\Local\Programs\Python\Python310\lib\site-packages\urllib3\util\ssl_.py", line 480, in ssl_wrap_socket
    ssl_sock = _ssl_wrap_socket_impl(sock, context, tls_in_tls, server_hostname)
  File "C:\Users\Gourav\AppData\Local\Programs\Python\Python310\lib\site-packages\urllib3\util\ssl_.py", line 524, in _ssl_wrap_socket_impl
    return ssl_context.wrap_socket(sock, server_hostname=server_hostname)
  File "C:\Users\Gourav\AppData\Local\Programs\Python\Python310\lib\ssl.py", line 513, in wrap_socket
    return self.sslsocket_class._create(
  File "C:\Users\Gourav\AppData\Local\Programs\Python\Python310\lib\ssl.py", line 1071, in _create
    self.do_handshake()
  File "C:\Users\Gourav\AppData\Local\Programs\Python\Python310\lib\ssl.py", line 1342, in do_handshake
    self._sslobj.do_handshake()
urllib3.exceptions.ProtocolError: ('Connection aborted.', ConnectionAbortedError(10053, 'An established connection was aborted by the software in your host machine', None, 10053, None))

During handling of the above exception, another exception occurred:

Traceback (most recent call last):
  File "d:\E2E Proj\main.py", line 13, in <module>
    obj.main()
  File "d:\e2e proj\src\cnnClassifier\pipeline\stage_01_data_ingestion.py", line 15, in main
    data_ingestion.download_file()
  File "d:\e2e proj\src\cnnClassifier\components\data_ingestion.py", line 31, in download_file
    raise e
  File "d:\e2e proj\src\cnnClassifier\components\data_ingestion.py", line 26, in download_file
    gdown.download(prefix+file_id, zip_download_dir)
  File "C:\Users\Gourav\AppData\Local\Programs\Python\Python310\lib\site-packages\gdown\download.py", line 202, in download
    res = sess.get(url, stream=True, verify=verify)
  File "C:\Users\Gourav\AppData\Local\Programs\Python\Python310\lib\site-packages\requests\sessions.py", line 602, in get
    return self.request("GET", url, **kwargs)
  File "C:\Users\Gourav\AppData\Local\Programs\Python\Python310\lib\site-packages\requests\sessions.py", line 589, in request
    resp = self.send(prep, **send_kwargs)
  File "C:\Users\Gourav\AppData\Local\Programs\Python\Python310\lib\site-packages\requests\sessions.py", line 703, in send
    r = adapter.send(request, **kwargs)
  File "C:\Users\Gourav\AppData\Local\Programs\Python\Python310\lib\site-packages\requests\adapters.py", line 682, in send
    raise ConnectionError(err, request=request)
requests.exceptions.ConnectionError: ('Connection aborted.', ConnectionAbortedError(10053, 'An established connection was aborted by the software in your host machine', None, 10053, None))
[2025-05-03 17:26:23,441: INFO: main: >>>>>>>> stage Data Ingestion Stage started here <<<<<<<<]
[2025-05-03 17:26:23,441: INFO: common: yaml file: config\config.yaml loaded successfully]
[2025-05-03 17:26:23,457: INFO: common: yaml file: params.yaml loaded successfully]
[2025-05-03 17:26:23,457: INFO: common: created directory at: artifacts]
[2025-05-03 17:26:23,458: INFO: common: created directory at: artifacts/data_ingestion]
[2025-05-03 17:26:23,459: INFO: data_ingestion: Downloading data from https://drive.google.com/file/d/1zsI3e2QVpuhM1hjHMlr-8lx6os6X2UQF/view?usp=sharing into file artifacts/data_ingestion/data.zip]
[2025-05-03 17:47:32,305: ERROR: main: ('Connection broken: IncompleteRead(1083873001 bytes read, 544046307 more expected)', IncompleteRead(1083873001 bytes read, 544046307 more expected))]
Traceback (most recent call last):
  File "C:\Users\Gourav\AppData\Local\Programs\Python\Python310\lib\site-packages\urllib3\response.py", line 754, in _error_catcher
    yield
  File "C:\Users\Gourav\AppData\Local\Programs\Python\Python310\lib\site-packages\urllib3\response.py", line 900, in _raw_read
    raise IncompleteRead(self._fp_bytes_read, self.length_remaining)
urllib3.exceptions.IncompleteRead: IncompleteRead(1083873001 bytes read, 544046307 more expected)

The above exception was the direct cause of the following exception:

Traceback (most recent call last):
  File "C:\Users\Gourav\AppData\Local\Programs\Python\Python310\lib\site-packages\requests\models.py", line 820, in generate
    yield from self.raw.stream(chunk_size, decode_content=True)
  File "C:\Users\Gourav\AppData\Local\Programs\Python\Python310\lib\site-packages\urllib3\response.py", line 1066, in stream
    data = self.read(amt=amt, decode_content=decode_content)
  File "C:\Users\Gourav\AppData\Local\Programs\Python\Python310\lib\site-packages\urllib3\response.py", line 983, in read
    data = self._raw_read(amt)
  File "C:\Users\Gourav\AppData\Local\Programs\Python\Python310\lib\site-packages\urllib3\response.py", line 878, in _raw_read
    with self._error_catcher():
  File "C:\Users\Gourav\AppData\Local\Programs\Python\Python310\lib\contextlib.py", line 153, in __exit__
    self.gen.throw(typ, value, traceback)
  File "C:\Users\Gourav\AppData\Local\Programs\Python\Python310\lib\site-packages\urllib3\response.py", line 778, in _error_catcher
    raise ProtocolError(arg, e) from e
urllib3.exceptions.ProtocolError: ('Connection broken: IncompleteRead(1083873001 bytes read, 544046307 more expected)', IncompleteRead(1083873001 bytes read, 544046307 more expected))

During handling of the above exception, another exception occurred:

Traceback (most recent call last):
  File "d:\E2E Proj\main.py", line 13, in <module>
    obj.main()
  File "d:\e2e proj\src\cnnClassifier\pipeline\stage_01_data_ingestion.py", line 15, in main
    data_ingestion.download_file()
  File "d:\e2e proj\src\cnnClassifier\components\data_ingestion.py", line 31, in download_file
    raise e
  File "d:\e2e proj\src\cnnClassifier\components\data_ingestion.py", line 26, in download_file
    gdown.download(prefix+file_id, zip_download_dir)
  File "C:\Users\Gourav\AppData\Local\Programs\Python\Python310\lib\site-packages\gdown\download.py", line 368, in download
    for chunk in res.iter_content(chunk_size=CHUNK_SIZE):
  File "C:\Users\Gourav\AppData\Local\Programs\Python\Python310\lib\site-packages\requests\models.py", line 822, in generate
    raise ChunkedEncodingError(e)
requests.exceptions.ChunkedEncodingError: ('Connection broken: IncompleteRead(1083873001 bytes read, 544046307 more expected)', IncompleteRead(1083873001 bytes read, 544046307 more expected))
[2025-05-09 21:10:53,128: INFO: main: >>>>>>>> stage Data Ingestion Stage started here <<<<<<<<]
[2025-05-09 21:10:53,140: INFO: common: yaml file: config\config.yaml loaded successfully]
[2025-05-09 21:10:53,154: INFO: common: yaml file: params.yaml loaded successfully]
[2025-05-09 21:10:53,155: INFO: common: created directory at: artifacts]
[2025-05-09 21:10:53,156: INFO: common: created directory at: artifacts/data_ingestion]
[2025-05-09 21:10:53,157: INFO: data_ingestion: Downloading data from https://drive.google.com/file/d/1zsI3e2QVpuhM1hjHMlr-8lx6os6X2UQF/view?usp=sharing into file artifacts/data_ingestion/data.zip]
[2025-05-09 21:14:01,545: INFO: data_ingestion: Downloaded data from https://drive.google.com/file/d/1zsI3e2QVpuhM1hjHMlr-8lx6os6X2UQF/view?usp=sharing into file artifacts/data_ingestion/data.zip]
[2025-05-09 21:14:17,220: INFO: main: >>>>>>>>> stage Data Ingestion Stage completed <<<<<<<<<

X=======================================================X]
[2025-05-09 21:14:17,220: INFO: main: >>>>>>>>>>>>>> Stage Model Preparation started <<<<<<<<<<<<<<]
[2025-05-09 21:14:17,220: INFO: common: yaml file: config\config.yaml loaded successfully]
[2025-05-09 21:14:17,220: INFO: common: yaml file: params.yaml loaded successfully]
[2025-05-09 21:14:17,220: INFO: common: created directory at: artifacts]
[2025-05-09 21:14:17,220: INFO: common: created directory at: artifacts/prepare_base_model]
[2025-05-09 21:14:19,836: WARNING: saving_utils: Compiled the loaded model, but the compiled metrics have yet to be built. `model.compile_metrics` will be empty until you train or evaluate the model.]
[2025-05-09 21:14:20,123: INFO: main: >>>>>>>>>>>> Stage Model Preparation COMPLETED <<<<<<<<<

X=========================================================X]
[2025-05-09 21:14:20,123: INFO: main: >>>>>>>>>>>>>> Stage Model Training started <<<<<<<<<<<<<<]
[2025-05-09 21:14:20,123: INFO: common: yaml file: config\config.yaml loaded successfully]
[2025-05-09 21:14:20,123: INFO: common: yaml file: params.yaml loaded successfully]
[2025-05-09 21:14:20,123: INFO: common: created directory at: artifacts]
[2025-05-09 21:14:20,123: INFO: common: created directory at: artifacts\trainig]
[2025-05-09 21:14:20,123: ERROR: main: TrainingConfig.__init__() missing 1 required positional argument: 'training_data']
Traceback (most recent call last):
  File "d:\E2E Proj\main.py", line 34, in <module>
    training_model.main()
  File "d:\e2e proj\src\cnnClassifier\pipeline\stage_03_model_training.py", line 15, in main
    training_config = config.get_training_config()
  File "d:\e2e proj\src\cnnClassifier\config\configuration.py", line 72, in get_training_config
    training_config = TrainingConfig(
TypeError: TrainingConfig.__init__() missing 1 required positional argument: 'training_data'
[2025-05-09 21:25:07,671: INFO: main: >>>>>>>> stage Data Ingestion Stage started here <<<<<<<<]
[2025-05-09 21:25:07,682: INFO: common: yaml file: config\config.yaml loaded successfully]
[2025-05-09 21:25:07,683: INFO: common: yaml file: params.yaml loaded successfully]
[2025-05-09 21:25:07,684: INFO: common: created directory at: artifacts]
[2025-05-09 21:25:07,684: INFO: common: created directory at: artifacts/data_ingestion]
[2025-05-09 21:25:07,685: INFO: data_ingestion: Downloading data from https://drive.google.com/file/d/1zsI3e2QVpuhM1hjHMlr-8lx6os6X2UQF/view?usp=sharing into file artifacts/data_ingestion/data.zip]
[2025-05-09 21:28:16,071: INFO: data_ingestion: Downloaded data from https://drive.google.com/file/d/1zsI3e2QVpuhM1hjHMlr-8lx6os6X2UQF/view?usp=sharing into file artifacts/data_ingestion/data.zip]
[2025-05-09 21:28:30,712: INFO: main: >>>>>>>>> stage Data Ingestion Stage completed <<<<<<<<<

X=======================================================X]
[2025-05-09 21:28:30,712: INFO: main: >>>>>>>>>>>>>> Stage Model Preparation started <<<<<<<<<<<<<<]
[2025-05-09 21:28:30,716: INFO: common: yaml file: config\config.yaml loaded successfully]
[2025-05-09 21:28:30,716: INFO: common: yaml file: params.yaml loaded successfully]
[2025-05-09 21:28:30,718: INFO: common: created directory at: artifacts]
[2025-05-09 21:28:30,718: INFO: common: created directory at: artifacts/prepare_base_model]
[2025-05-09 21:28:31,710: WARNING: saving_utils: Compiled the loaded model, but the compiled metrics have yet to be built. `model.compile_metrics` will be empty until you train or evaluate the model.]
[2025-05-09 21:28:32,023: INFO: main: >>>>>>>>>>>> Stage Model Preparation COMPLETED <<<<<<<<<

X=========================================================X]
[2025-05-09 21:28:32,023: INFO: main: >>>>>>>>>>>>>> Stage Model Training started <<<<<<<<<<<<<<]
[2025-05-09 21:28:32,023: INFO: common: yaml file: config\config.yaml loaded successfully]
[2025-05-09 21:28:32,023: INFO: common: yaml file: params.yaml loaded successfully]
[2025-05-09 21:28:32,023: INFO: common: created directory at: artifacts]
[2025-05-09 21:28:32,023: INFO: common: created directory at: artifacts\trainig]
[2025-05-09 21:28:32,663: ERROR: main: unsupported operand type(s) for ** or pow(): 'bool' and 'dict']
Traceback (most recent call last):
  File "d:\E2E Proj\main.py", line 34, in <module>
    training_model.main()
  File "d:\e2e proj\src\cnnClassifier\pipeline\stage_03_model_training.py", line 18, in main
    training.train_valid_genrator()
  File "d:\e2e proj\src\cnnClassifier\components\training_data.py", line 38, in train_valid_genrator
    shuffle = False
TypeError: unsupported operand type(s) for ** or pow(): 'bool' and 'dict'
[2025-05-09 21:32:33,233: INFO: main: >>>>>>>> stage Data Ingestion Stage started here <<<<<<<<]
[2025-05-09 21:32:33,233: INFO: common: yaml file: config\config.yaml loaded successfully]
[2025-05-09 21:32:33,233: INFO: common: yaml file: params.yaml loaded successfully]
[2025-05-09 21:32:33,233: INFO: common: created directory at: artifacts]
[2025-05-09 21:32:33,233: INFO: common: created directory at: artifacts/data_ingestion]
[2025-05-09 21:32:33,233: INFO: data_ingestion: Downloading data from https://drive.google.com/file/d/1zsI3e2QVpuhM1hjHMlr-8lx6os6X2UQF/view?usp=sharing into file artifacts/data_ingestion/data.zip]
[2025-05-09 21:36:00,842: INFO: data_ingestion: Downloaded data from https://drive.google.com/file/d/1zsI3e2QVpuhM1hjHMlr-8lx6os6X2UQF/view?usp=sharing into file artifacts/data_ingestion/data.zip]
[2025-05-09 21:36:16,458: INFO: main: >>>>>>>>> stage Data Ingestion Stage completed <<<<<<<<<

X=======================================================X]
[2025-05-09 21:36:16,458: INFO: main: >>>>>>>>>>>>>> Stage Model Preparation started <<<<<<<<<<<<<<]
[2025-05-09 21:36:16,463: INFO: common: yaml file: config\config.yaml loaded successfully]
[2025-05-09 21:36:16,463: INFO: common: yaml file: params.yaml loaded successfully]
[2025-05-09 21:36:16,463: INFO: common: created directory at: artifacts]
[2025-05-09 21:36:16,463: INFO: common: created directory at: artifacts/prepare_base_model]
[2025-05-09 21:36:17,452: WARNING: saving_utils: Compiled the loaded model, but the compiled metrics have yet to be built. `model.compile_metrics` will be empty until you train or evaluate the model.]
[2025-05-09 21:36:18,658: INFO: main: >>>>>>>>>>>> Stage Model Preparation COMPLETED <<<<<<<<<

X=========================================================X]
[2025-05-09 21:36:18,658: INFO: main: >>>>>>>>>>>>>> Stage Model Training started <<<<<<<<<<<<<<]
[2025-05-09 21:36:18,674: INFO: common: yaml file: config\config.yaml loaded successfully]
[2025-05-09 21:36:18,674: INFO: common: yaml file: params.yaml loaded successfully]
[2025-05-09 21:36:18,674: INFO: common: created directory at: artifacts]
[2025-05-09 21:36:18,674: INFO: common: created directory at: artifacts\trainig]
[2025-05-09 21:36:18,949: ERROR: main: [WinError 3] The system cannot find the path specified: 'artifacts\\data_ingestion\\kidney-ct-scan-image']
Traceback (most recent call last):
  File "d:\E2E Proj\main.py", line 34, in <module>
    training_model.main()
  File "d:\e2e proj\src\cnnClassifier\pipeline\stage_03_model_training.py", line 18, in main
    training.train_valid_genrator()
  File "d:\e2e proj\src\cnnClassifier\components\training_data.py", line 35, in train_valid_genrator
    self.valid_generator = valid_datagenerator.flow_from_directory(
  File "C:\Users\Gourav\AppData\Local\Programs\Python\Python310\lib\site-packages\keras\preprocessing\image.py", line 1650, in flow_from_directory
    return DirectoryIterator(
  File "C:\Users\Gourav\AppData\Local\Programs\Python\Python310\lib\site-packages\keras\preprocessing\image.py", line 563, in __init__
    for subdir in sorted(os.listdir(directory)):
FileNotFoundError: [WinError 3] The system cannot find the path specified: 'artifacts\\data_ingestion\\kidney-ct-scan-image'
[2025-05-24 16:21:40,838: INFO: main: >>>>>>>> stage Data Ingestion Stage started here <<<<<<<<]
[2025-05-24 16:21:40,855: INFO: common: yaml file: config\config.yaml loaded successfully]
[2025-05-24 16:21:40,869: INFO: common: yaml file: params.yaml loaded successfully]
[2025-05-24 16:21:40,871: INFO: common: created directory at: artifacts]
[2025-05-24 16:21:40,872: INFO: common: created directory at: artifacts/data_ingestion]
[2025-05-24 16:21:40,873: INFO: data_ingestion: Downloading data from https://drive.google.com/file/d/1zsI3e2QVpuhM1hjHMlr-8lx6os6X2UQF/view?usp=sharing into file artifacts/data_ingestion/data.zip]
[2025-05-24 16:23:24,258: INFO: data_ingestion: Downloaded data from https://drive.google.com/file/d/1zsI3e2QVpuhM1hjHMlr-8lx6os6X2UQF/view?usp=sharing into file artifacts/data_ingestion/data.zip]
[2025-05-24 16:23:51,947: INFO: main: >>>>>>>>> stage Data Ingestion Stage completed <<<<<<<<<

X=======================================================X]
[2025-05-24 16:23:51,948: INFO: main: >>>>>>>>>>>>>> Stage Model Preparation started <<<<<<<<<<<<<<]
[2025-05-24 16:23:51,953: INFO: common: yaml file: config\config.yaml loaded successfully]
[2025-05-24 16:23:51,954: INFO: common: yaml file: params.yaml loaded successfully]
[2025-05-24 16:23:51,956: INFO: common: created directory at: artifacts]
[2025-05-24 16:23:51,957: INFO: common: created directory at: artifacts/prepare_base_model]
[2025-05-24 16:23:56,361: WARNING: saving_utils: Compiled the loaded model, but the compiled metrics have yet to be built. `model.compile_metrics` will be empty until you train or evaluate the model.]
[2025-05-24 16:23:56,808: INFO: main: >>>>>>>>>>>> Stage Model Preparation COMPLETED <<<<<<<<<

X=========================================================X]
[2025-05-24 16:23:56,808: INFO: main: >>>>>>>>>>>>>> Stage Model Training started <<<<<<<<<<<<<<]
[2025-05-24 16:23:56,811: INFO: common: yaml file: config\config.yaml loaded successfully]
[2025-05-24 16:23:56,813: INFO: common: yaml file: params.yaml loaded successfully]
[2025-05-24 16:23:56,813: INFO: common: created directory at: artifacts]
[2025-05-24 16:23:56,814: INFO: common: created directory at: artifacts\trainig]
[2025-05-24 16:23:57,212: ERROR: main: [WinError 3] The system cannot find the path specified: 'artifacts\\data_ingestion\\kidney-ct-scan-image']
Traceback (most recent call last):
  File "d:\E2E Proj\main.py", line 34, in <module>
    training_model.main()
  File "d:\e2e proj\src\cnnClassifier\pipeline\stage_03_model_training.py", line 18, in main
    training.train_valid_genrator()
  File "d:\e2e proj\src\cnnClassifier\components\training_data.py", line 35, in train_valid_genrator
    self.valid_generator = valid_datagenerator.flow_from_directory(
  File "C:\Users\Gourav\AppData\Local\Programs\Python\Python310\lib\site-packages\keras\preprocessing\image.py", line 1650, in flow_from_directory
    return DirectoryIterator(
  File "C:\Users\Gourav\AppData\Local\Programs\Python\Python310\lib\site-packages\keras\preprocessing\image.py", line 563, in __init__
    for subdir in sorted(os.listdir(directory)):
FileNotFoundError: [WinError 3] The system cannot find the path specified: 'artifacts\\data_ingestion\\kidney-ct-scan-image'
[2025-05-24 17:06:18,970: INFO: main: >>>>>>>> stage Data Ingestion Stage started here <<<<<<<<]
[2025-05-24 17:06:18,980: INFO: common: yaml file: config\config.yaml loaded successfully]
[2025-05-24 17:06:18,980: INFO: common: yaml file: params.yaml loaded successfully]
[2025-05-24 17:06:18,980: INFO: common: created directory at: artifacts]
[2025-05-24 17:06:18,990: INFO: common: created directory at: artifacts/data_ingestion]
[2025-05-24 17:06:18,992: INFO: data_ingestion: Downloading data from https://drive.google.com/file/d/1zsI3e2QVpuhM1hjHMlr-8lx6os6X2UQF/view?usp=sharing into file artifacts/data_ingestion/kidney-ct-scan-image.zip]
[2025-05-24 17:07:33,508: INFO: data_ingestion: Downloaded data from https://drive.google.com/file/d/1zsI3e2QVpuhM1hjHMlr-8lx6os6X2UQF/view?usp=sharing into file artifacts/data_ingestion/kidney-ct-scan-image.zip]
[2025-05-24 17:08:00,337: INFO: main: >>>>>>>>> stage Data Ingestion Stage completed <<<<<<<<<

X=======================================================X]
[2025-05-24 17:08:00,337: INFO: main: >>>>>>>>>>>>>> Stage Model Preparation started <<<<<<<<<<<<<<]
[2025-05-24 17:08:00,337: INFO: common: yaml file: config\config.yaml loaded successfully]
[2025-05-24 17:08:00,337: INFO: common: yaml file: params.yaml loaded successfully]
[2025-05-24 17:08:00,337: INFO: common: created directory at: artifacts]
[2025-05-24 17:08:00,337: INFO: common: created directory at: artifacts/prepare_base_model]
[2025-05-24 17:08:02,794: WARNING: saving_utils: Compiled the loaded model, but the compiled metrics have yet to be built. `model.compile_metrics` will be empty until you train or evaluate the model.]
[2025-05-24 17:08:03,146: INFO: main: >>>>>>>>>>>> Stage Model Preparation COMPLETED <<<<<<<<<

X=========================================================X]
[2025-05-24 17:08:03,146: INFO: main: >>>>>>>>>>>>>> Stage Model Training started <<<<<<<<<<<<<<]
[2025-05-24 17:08:03,146: INFO: common: yaml file: config\config.yaml loaded successfully]
[2025-05-24 17:08:03,161: INFO: common: yaml file: params.yaml loaded successfully]
[2025-05-24 17:08:03,161: INFO: common: created directory at: artifacts]
[2025-05-24 17:08:03,161: INFO: common: created directory at: artifacts\training]
[2025-05-24 17:08:03,643: ERROR: main: 'TrainingConfig' object has no attribute 'params_is_augmentation']
Traceback (most recent call last):
  File "d:\E2E Proj\main.py", line 34, in <module>
    training_model.main()
  File "d:\e2e proj\src\cnnClassifier\pipeline\stage_03_model_training.py", line 18, in main
    training.train_valid_genrator()
  File "d:\e2e proj\src\cnnClassifier\components\training_data.py", line 42, in train_valid_genrator
    if self.config.params_is_augmentation:
AttributeError: 'TrainingConfig' object has no attribute 'params_is_augmentation'
[2025-05-24 17:11:05,056: INFO: main: >>>>>>>> stage Data Ingestion Stage started here <<<<<<<<]
[2025-05-24 17:11:05,058: INFO: common: yaml file: config\config.yaml loaded successfully]
[2025-05-24 17:11:05,059: INFO: common: yaml file: params.yaml loaded successfully]
[2025-05-24 17:11:05,060: INFO: common: created directory at: artifacts]
[2025-05-24 17:11:05,060: INFO: common: created directory at: artifacts/data_ingestion]
[2025-05-24 17:11:05,061: INFO: data_ingestion: Downloading data from https://drive.google.com/file/d/1zsI3e2QVpuhM1hjHMlr-8lx6os6X2UQF/view?usp=sharing into file artifacts/data_ingestion/kidney-ct-scan-image.zip]
[2025-05-24 17:12:56,011: INFO: data_ingestion: Downloaded data from https://drive.google.com/file/d/1zsI3e2QVpuhM1hjHMlr-8lx6os6X2UQF/view?usp=sharing into file artifacts/data_ingestion/kidney-ct-scan-image.zip]
[2025-05-24 17:13:11,226: INFO: main: >>>>>>>>> stage Data Ingestion Stage completed <<<<<<<<<

X=======================================================X]
[2025-05-24 17:13:11,226: INFO: main: >>>>>>>>>>>>>> Stage Model Preparation started <<<<<<<<<<<<<<]
[2025-05-24 17:13:11,226: INFO: common: yaml file: config\config.yaml loaded successfully]
[2025-05-24 17:13:11,226: INFO: common: yaml file: params.yaml loaded successfully]
[2025-05-24 17:13:11,226: INFO: common: created directory at: artifacts]
[2025-05-24 17:13:11,226: INFO: common: created directory at: artifacts/prepare_base_model]
[2025-05-24 17:13:12,244: WARNING: saving_utils: Compiled the loaded model, but the compiled metrics have yet to be built. `model.compile_metrics` will be empty until you train or evaluate the model.]
[2025-05-24 17:13:12,962: INFO: main: >>>>>>>>>>>> Stage Model Preparation COMPLETED <<<<<<<<<

X=========================================================X]
[2025-05-24 17:13:12,962: INFO: main: >>>>>>>>>>>>>> Stage Model Training started <<<<<<<<<<<<<<]
[2025-05-24 17:13:12,962: INFO: common: yaml file: config\config.yaml loaded successfully]
[2025-05-24 17:13:12,962: INFO: common: yaml file: params.yaml loaded successfully]
[2025-05-24 17:13:12,962: INFO: common: created directory at: artifacts]
[2025-05-24 17:13:12,962: INFO: common: created directory at: artifacts\training]
[2025-05-24 17:13:12,962: ERROR: main: TrainingConfig.__init__() got an unexpected keyword argument 'params_is_augmetation']
Traceback (most recent call last):
  File "d:\E2E Proj\main.py", line 34, in <module>
    training_model.main()
  File "d:\e2e proj\src\cnnClassifier\pipeline\stage_03_model_training.py", line 15, in main
    training_config = config.get_training_config()
  File "d:\e2e proj\src\cnnClassifier\config\configuration.py", line 72, in get_training_config
    training_config = TrainingConfig(
TypeError: TrainingConfig.__init__() got an unexpected keyword argument 'params_is_augmetation'
[2025-05-24 17:17:11,228: INFO: main: >>>>>>>> stage Data Ingestion Stage started here <<<<<<<<]
[2025-05-24 17:17:11,228: INFO: common: yaml file: config\config.yaml loaded successfully]
[2025-05-24 17:17:11,228: INFO: common: yaml file: params.yaml loaded successfully]
[2025-05-24 17:17:11,228: INFO: common: created directory at: artifacts]
[2025-05-24 17:17:11,228: INFO: common: created directory at: artifacts/data_ingestion]
[2025-05-24 17:17:11,228: INFO: data_ingestion: Downloading data from https://drive.google.com/file/d/1zsI3e2QVpuhM1hjHMlr-8lx6os6X2UQF/view?usp=sharing into file artifacts/data_ingestion/kidney-ct-scan-image.zip]
[2025-05-24 17:18:35,493: INFO: data_ingestion: Downloaded data from https://drive.google.com/file/d/1zsI3e2QVpuhM1hjHMlr-8lx6os6X2UQF/view?usp=sharing into file artifacts/data_ingestion/kidney-ct-scan-image.zip]
[2025-05-24 17:18:55,655: INFO: main: >>>>>>>>> stage Data Ingestion Stage completed <<<<<<<<<

X=======================================================X]
[2025-05-24 17:18:55,655: INFO: main: >>>>>>>>>>>>>> Stage Model Preparation started <<<<<<<<<<<<<<]
[2025-05-24 17:18:55,658: INFO: common: yaml file: config\config.yaml loaded successfully]
[2025-05-24 17:18:55,659: INFO: common: yaml file: params.yaml loaded successfully]
[2025-05-24 17:18:55,660: INFO: common: created directory at: artifacts]
[2025-05-24 17:18:55,660: INFO: common: created directory at: artifacts/prepare_base_model]
[2025-05-24 17:18:57,073: WARNING: saving_utils: Compiled the loaded model, but the compiled metrics have yet to be built. `model.compile_metrics` will be empty until you train or evaluate the model.]
[2025-05-24 17:18:58,078: INFO: main: >>>>>>>>>>>> Stage Model Preparation COMPLETED <<<<<<<<<

X=========================================================X]
[2025-05-24 17:18:58,078: INFO: main: >>>>>>>>>>>>>> Stage Model Training started <<<<<<<<<<<<<<]
[2025-05-24 17:18:58,082: INFO: common: yaml file: config\config.yaml loaded successfully]
[2025-05-24 17:18:58,085: INFO: common: yaml file: params.yaml loaded successfully]
[2025-05-24 17:18:58,085: INFO: common: created directory at: artifacts]
[2025-05-24 17:18:58,090: INFO: common: created directory at: artifacts\training]
[2025-05-24 17:18:59,231: ERROR: main: Training.train() missing 1 required positional argument: 'callback_list']
Traceback (most recent call last):
  File "d:\E2E Proj\main.py", line 34, in <module>
    training_model.main()
  File "d:\e2e proj\src\cnnClassifier\pipeline\stage_03_model_training.py", line 19, in main
    training.train()
TypeError: Training.train() missing 1 required positional argument: 'callback_list'
[2025-05-24 17:47:51,333: INFO: main: >>>>>>>>>>>>>> Stage Model Preparation started <<<<<<<<<<<<<<]
[2025-05-24 17:47:51,334: INFO: common: yaml file: config\config.yaml loaded successfully]
[2025-05-24 17:47:51,336: INFO: common: yaml file: params.yaml loaded successfully]
[2025-05-24 17:47:51,336: INFO: common: created directory at: artifacts]
[2025-05-24 17:47:51,336: INFO: common: created directory at: artifacts/prepare_base_model]
[2025-05-24 17:47:52,475: WARNING: saving_utils: Compiled the loaded model, but the compiled metrics have yet to be built. `model.compile_metrics` will be empty until you train or evaluate the model.]
[2025-05-24 17:47:52,735: INFO: main: >>>>>>>>>>>> Stage Model Preparation COMPLETED <<<<<<<<<

X=========================================================X]
[2025-05-24 17:47:52,735: INFO: main: >>>>>>>>>>>>>> Stage Model Training started <<<<<<<<<<<<<<]
[2025-05-24 17:47:52,735: INFO: common: yaml file: config\config.yaml loaded successfully]
[2025-05-24 17:47:52,735: INFO: common: yaml file: params.yaml loaded successfully]
[2025-05-24 17:47:52,735: INFO: common: created directory at: artifacts]
[2025-05-24 17:47:52,735: INFO: common: created directory at: artifacts\training]
[2025-05-24 17:47:53,334: ERROR: main: Training.train() missing 1 required positional argument: 'callback_list']
Traceback (most recent call last):
  File "d:\E2E Proj\main.py", line 34, in <module>
    training_model.main()
  File "d:\e2e proj\src\cnnClassifier\pipeline\stage_03_model_training.py", line 19, in main
    training.train()
TypeError: Training.train() missing 1 required positional argument: 'callback_list'
[2025-05-24 17:49:34,143: INFO: main: >>>>>>>>>>>>>> Stage Model Preparation started <<<<<<<<<<<<<<]
[2025-05-24 17:49:34,144: INFO: common: yaml file: config\config.yaml loaded successfully]
[2025-05-24 17:49:34,146: INFO: common: yaml file: params.yaml loaded successfully]
[2025-05-24 17:49:34,146: INFO: common: created directory at: artifacts]
[2025-05-24 17:49:34,147: INFO: common: created directory at: artifacts/prepare_base_model]
[2025-05-24 17:49:35,173: WARNING: saving_utils: Compiled the loaded model, but the compiled metrics have yet to be built. `model.compile_metrics` will be empty until you train or evaluate the model.]
[2025-05-24 17:49:35,475: INFO: main: >>>>>>>>>>>> Stage Model Preparation COMPLETED <<<<<<<<<

X=========================================================X]
[2025-05-24 17:49:35,475: INFO: main: >>>>>>>>>>>>>> Stage Model Training started <<<<<<<<<<<<<<]
[2025-05-24 17:49:35,477: INFO: common: yaml file: config\config.yaml loaded successfully]
[2025-05-24 17:49:35,478: INFO: common: yaml file: params.yaml loaded successfully]
[2025-05-24 17:49:35,478: INFO: common: created directory at: artifacts]
[2025-05-24 17:49:35,479: INFO: common: created directory at: artifacts\training]
[2025-05-24 17:49:36,084: ERROR: main: 'Training' object has no attribute 'train']
Traceback (most recent call last):
  File "d:\E2E Proj\main.py", line 34, in <module>
    training_model.main()
  File "d:\e2e proj\src\cnnClassifier\pipeline\stage_03_model_training.py", line 19, in main
    training.train()
AttributeError: 'Training' object has no attribute 'train'
[2025-05-24 17:53:56,909: INFO: main: >>>>>>>>>>>>>> Stage Model Preparation started <<<<<<<<<<<<<<]
[2025-05-24 17:53:56,909: INFO: common: yaml file: config\config.yaml loaded successfully]
[2025-05-24 17:53:56,909: INFO: common: yaml file: params.yaml loaded successfully]
[2025-05-24 17:53:56,909: INFO: common: created directory at: artifacts]
[2025-05-24 17:53:56,909: INFO: common: created directory at: artifacts/prepare_base_model]
[2025-05-24 17:53:57,950: WARNING: saving_utils: Compiled the loaded model, but the compiled metrics have yet to be built. `model.compile_metrics` will be empty until you train or evaluate the model.]
[2025-05-24 17:53:58,247: INFO: main: >>>>>>>>>>>> Stage Model Preparation COMPLETED <<<<<<<<<

X=========================================================X]
[2025-05-24 17:53:58,247: INFO: main: >>>>>>>>>>>>>> Stage Model Training started <<<<<<<<<<<<<<]
[2025-05-24 17:53:58,249: INFO: common: yaml file: config\config.yaml loaded successfully]
[2025-05-24 17:53:58,250: INFO: common: yaml file: params.yaml loaded successfully]
[2025-05-24 17:53:58,250: INFO: common: created directory at: artifacts]
[2025-05-24 17:53:58,251: INFO: common: created directory at: artifacts\training]
[2025-05-24 17:53:58,859: ERROR: main: 'Training' object has no attribute 'train']
Traceback (most recent call last):
  File "d:\E2E Proj\main.py", line 34, in <module>
    training_model.main()
  File "d:\e2e proj\src\cnnClassifier\pipeline\stage_03_model_training.py", line 19, in main
    training.train()
AttributeError: 'Training' object has no attribute 'train'
[2025-05-24 17:55:05,910: INFO: main: >>>>>>>>>>>>>> Stage Model Preparation started <<<<<<<<<<<<<<]
[2025-05-24 17:55:05,910: INFO: common: yaml file: config\config.yaml loaded successfully]
[2025-05-24 17:55:05,910: INFO: common: yaml file: params.yaml loaded successfully]
[2025-05-24 17:55:05,910: INFO: common: created directory at: artifacts]
[2025-05-24 17:55:05,910: INFO: common: created directory at: artifacts/prepare_base_model]
[2025-05-24 17:55:06,834: WARNING: saving_utils: Compiled the loaded model, but the compiled metrics have yet to be built. `model.compile_metrics` will be empty until you train or evaluate the model.]
[2025-05-24 17:55:07,096: INFO: main: >>>>>>>>>>>> Stage Model Preparation COMPLETED <<<<<<<<<

X=========================================================X]
[2025-05-24 17:55:07,096: INFO: main: >>>>>>>>>>>>>> Stage Model Training started <<<<<<<<<<<<<<]
[2025-05-24 17:55:07,096: INFO: common: yaml file: config\config.yaml loaded successfully]
[2025-05-24 17:55:07,096: INFO: common: yaml file: params.yaml loaded successfully]
[2025-05-24 17:55:07,096: INFO: common: created directory at: artifacts]
[2025-05-24 17:55:07,096: INFO: common: created directory at: artifacts\training]
[2025-05-24 17:55:07,342: ERROR: main: 'Training' object has no attribute 'train_valid_genrator']
Traceback (most recent call last):
  File "d:\E2E Proj\main.py", line 34, in <module>
    training_model.main()
  File "d:\e2e proj\src\cnnClassifier\pipeline\stage_03_model_training.py", line 18, in main
    training.train_valid_genrator()
AttributeError: 'Training' object has no attribute 'train_valid_genrator'
[2025-05-24 17:58:05,952: INFO: main: >>>>>>>>>>>>>> Stage Model Preparation started <<<<<<<<<<<<<<]
[2025-05-24 17:58:05,954: INFO: common: yaml file: config\config.yaml loaded successfully]
[2025-05-24 17:58:05,955: INFO: common: yaml file: params.yaml loaded successfully]
[2025-05-24 17:58:05,956: INFO: common: created directory at: artifacts]
[2025-05-24 17:58:05,956: INFO: common: created directory at: artifacts/prepare_base_model]
[2025-05-24 17:58:06,898: WARNING: saving_utils: Compiled the loaded model, but the compiled metrics have yet to be built. `model.compile_metrics` will be empty until you train or evaluate the model.]
[2025-05-24 17:58:07,173: INFO: main: >>>>>>>>>>>> Stage Model Preparation COMPLETED <<<<<<<<<

X=========================================================X]
[2025-05-24 17:58:07,173: INFO: main: >>>>>>>>>>>>>> Stage Model Training started <<<<<<<<<<<<<<]
[2025-05-24 17:58:07,173: INFO: common: yaml file: config\config.yaml loaded successfully]
[2025-05-24 17:58:07,176: INFO: common: yaml file: params.yaml loaded successfully]
[2025-05-24 17:58:07,176: INFO: common: created directory at: artifacts]
[2025-05-24 17:58:07,176: INFO: common: created directory at: artifacts\training]
[2025-05-24 18:11:27,934: INFO: main: >>>>>>>>>>>>>> Stage Model Preparation started <<<<<<<<<<<<<<]
[2025-05-24 18:11:27,947: INFO: common: yaml file: config\config.yaml loaded successfully]
[2025-05-24 18:11:27,960: INFO: common: yaml file: params.yaml loaded successfully]
[2025-05-24 18:11:27,960: INFO: common: created directory at: artifacts]
[2025-05-24 18:11:27,960: INFO: common: created directory at: artifacts/prepare_base_model]
[2025-05-24 18:11:30,041: WARNING: saving_utils: Compiled the loaded model, but the compiled metrics have yet to be built. `model.compile_metrics` will be empty until you train or evaluate the model.]
[2025-05-24 18:11:30,854: INFO: main: >>>>>>>>>>>> Stage Model Preparation COMPLETED <<<<<<<<<

X=========================================================X]
[2025-05-24 18:11:30,854: INFO: main: >>>>>>>>>>>>>> Stage Model Training started <<<<<<<<<<<<<<]
[2025-05-24 18:11:30,854: INFO: common: yaml file: config\config.yaml loaded successfully]
[2025-05-24 18:11:30,854: INFO: common: yaml file: params.yaml loaded successfully]
[2025-05-24 18:11:30,854: INFO: common: created directory at: artifacts]
[2025-05-24 18:11:30,854: INFO: common: created directory at: artifacts\training]
[2025-05-24 18:47:31,518: INFO: main: >>>>>>>>>>>> Stage Model Training COMPLETED <<<<<<<<<

X=========================================================X]
[2025-05-24 18:58:29,060: INFO: main: >>>>>>>>>>>>>> Stage Model Preparation started <<<<<<<<<<<<<<]
[2025-05-24 18:58:29,060: INFO: common: yaml file: config\config.yaml loaded successfully]
[2025-05-24 18:58:29,060: INFO: common: yaml file: params.yaml loaded successfully]
[2025-05-24 18:58:29,060: INFO: common: created directory at: artifacts]
[2025-05-24 18:58:29,060: INFO: common: created directory at: artifacts/prepare_base_model]
[2025-05-24 18:58:30,031: WARNING: saving_utils: Compiled the loaded model, but the compiled metrics have yet to be built. `model.compile_metrics` will be empty until you train or evaluate the model.]
[2025-05-24 18:58:30,318: INFO: main: >>>>>>>>>>>> Stage Model Preparation COMPLETED <<<<<<<<<

X=========================================================X]
[2025-05-24 18:58:30,318: INFO: main: >>>>>>>>>>>>>> Stage Model Training started <<<<<<<<<<<<<<]
[2025-05-24 18:58:30,318: INFO: common: yaml file: config\config.yaml loaded successfully]
[2025-05-24 18:58:30,318: INFO: common: yaml file: params.yaml loaded successfully]
[2025-05-24 18:58:30,318: INFO: common: created directory at: artifacts]
[2025-05-24 18:58:30,318: INFO: common: created directory at: artifacts\training]
[2025-05-24 19:03:13,245: INFO: main: >>>>>>>>>>>>>> Stage Model Preparation started <<<<<<<<<<<<<<]
[2025-05-24 19:03:13,245: INFO: common: yaml file: config\config.yaml loaded successfully]
[2025-05-24 19:03:13,245: INFO: common: yaml file: params.yaml loaded successfully]
[2025-05-24 19:03:13,245: INFO: common: created directory at: artifacts]
[2025-05-24 19:03:13,245: INFO: common: created directory at: artifacts/prepare_base_model]
[2025-05-24 19:03:14,134: WARNING: saving_utils: Compiled the loaded model, but the compiled metrics have yet to be built. `model.compile_metrics` will be empty until you train or evaluate the model.]
[2025-05-24 19:03:14,402: INFO: main: >>>>>>>>>>>> Stage Model Preparation COMPLETED <<<<<<<<<

X=========================================================X]
[2025-05-24 19:03:14,402: INFO: main: >>>>>>>>>>>>>> Stage Model Training started <<<<<<<<<<<<<<]
[2025-05-24 19:03:14,418: INFO: common: yaml file: config\config.yaml loaded successfully]
[2025-05-24 19:03:14,418: INFO: common: yaml file: params.yaml loaded successfully]
[2025-05-24 19:03:14,418: INFO: common: created directory at: artifacts]
[2025-05-24 19:03:14,418: INFO: common: created directory at: artifacts\training]
[2025-05-24 19:07:00,985: ERROR: main: Graph execution error:

2 root error(s) found.
  (0) UNKNOWN:  FileNotFoundError: [Errno 2] No such file or directory: 'artifacts\\data_ingestion\\kidney-ct-scan-image\\CT-KIDNEY-DATASET-Normal-Cyst-Tumor-Stone\\CT-KIDNEY-DATASET-Normal-Cyst-Tumor-Stone\\Cyst\\Cyst- (819).jpg'
Traceback (most recent call last):

  File "C:\Users\Gourav\AppData\Local\Programs\Python\Python310\lib\site-packages\tensorflow\python\ops\script_ops.py", line 271, in __call__
    ret = func(*args)

  File "C:\Users\Gourav\AppData\Local\Programs\Python\Python310\lib\site-packages\tensorflow\python\autograph\impl\api.py", line 642, in wrapper
    return func(*args, **kwargs)

  File "C:\Users\Gourav\AppData\Local\Programs\Python\Python310\lib\site-packages\tensorflow\python\data\ops\dataset_ops.py", line 1035, in generator_py_func
    values = next(generator_state.get_iterator(iterator_id))

  File "C:\Users\Gourav\AppData\Local\Programs\Python\Python310\lib\site-packages\keras\engine\data_adapter.py", line 903, in wrapped_generator
    for data in generator_fn():

  File "C:\Users\Gourav\AppData\Local\Programs\Python\Python310\lib\site-packages\keras\engine\data_adapter.py", line 1050, in generator_fn
    yield x[i]

  File "C:\Users\Gourav\AppData\Local\Programs\Python\Python310\lib\site-packages\keras\preprocessing\image.py", line 116, in __getitem__
    return self._get_batches_of_transformed_samples(index_array)

  File "C:\Users\Gourav\AppData\Local\Programs\Python\Python310\lib\site-packages\keras\preprocessing\image.py", line 370, in _get_batches_of_transformed_samples
    img = image_utils.load_img(

  File "C:\Users\Gourav\AppData\Local\Programs\Python\Python310\lib\site-packages\keras\utils\image_utils.py", line 422, in load_img
    with open(path, "rb") as f:

FileNotFoundError: [Errno 2] No such file or directory: 'artifacts\\data_ingestion\\kidney-ct-scan-image\\CT-KIDNEY-DATASET-Normal-Cyst-Tumor-Stone\\CT-KIDNEY-DATASET-Normal-Cyst-Tumor-Stone\\Cyst\\Cyst- (819).jpg'


	 [[{{node PyFunc}}]]
	 [[IteratorGetNext]]
	 [[IteratorGetNext/_2]]
  (1) UNKNOWN:  FileNotFoundError: [Errno 2] No such file or directory: 'artifacts\\data_ingestion\\kidney-ct-scan-image\\CT-KIDNEY-DATASET-Normal-Cyst-Tumor-Stone\\CT-KIDNEY-DATASET-Normal-Cyst-Tumor-Stone\\Cyst\\Cyst- (819).jpg'
Traceback (most recent call last):

  File "C:\Users\Gourav\AppData\Local\Programs\Python\Python310\lib\site-packages\tensorflow\python\ops\script_ops.py", line 271, in __call__
    ret = func(*args)

  File "C:\Users\Gourav\AppData\Local\Programs\Python\Python310\lib\site-packages\tensorflow\python\autograph\impl\api.py", line 642, in wrapper
    return func(*args, **kwargs)

  File "C:\Users\Gourav\AppData\Local\Programs\Python\Python310\lib\site-packages\tensorflow\python\data\ops\dataset_ops.py", line 1035, in generator_py_func
    values = next(generator_state.get_iterator(iterator_id))

  File "C:\Users\Gourav\AppData\Local\Programs\Python\Python310\lib\site-packages\keras\engine\data_adapter.py", line 903, in wrapped_generator
    for data in generator_fn():

  File "C:\Users\Gourav\AppData\Local\Programs\Python\Python310\lib\site-packages\keras\engine\data_adapter.py", line 1050, in generator_fn
    yield x[i]

  File "C:\Users\Gourav\AppData\Local\Programs\Python\Python310\lib\site-packages\keras\preprocessing\image.py", line 116, in __getitem__
    return self._get_batches_of_transformed_samples(index_array)

  File "C:\Users\Gourav\AppData\Local\Programs\Python\Python310\lib\site-packages\keras\preprocessing\image.py", line 370, in _get_batches_of_transformed_samples
    img = image_utils.load_img(

  File "C:\Users\Gourav\AppData\Local\Programs\Python\Python310\lib\site-packages\keras\utils\image_utils.py", line 422, in load_img
    with open(path, "rb") as f:

FileNotFoundError: [Errno 2] No such file or directory: 'artifacts\\data_ingestion\\kidney-ct-scan-image\\CT-KIDNEY-DATASET-Normal-Cyst-Tumor-Stone\\CT-KIDNEY-DATASET-Normal-Cyst-Tumor-Stone\\Cyst\\Cyst- (819).jpg'


	 [[{{node PyFunc}}]]
	 [[IteratorGetNext]]
0 successful operations.
0 derived errors ignored. [Op:__inference_train_function_1909]]
Traceback (most recent call last):
  File "d:\E2E Proj\main.py", line 34, in <module>
    training_model.main()
  File "d:\e2e proj\src\cnnClassifier\pipeline\stage_03_model_training.py", line 19, in main
    training.train()
  File "d:\e2e proj\src\cnnClassifier\components\training_data.py", line 77, in train
    self.model.fit(
  File "C:\Users\Gourav\AppData\Local\Programs\Python\Python310\lib\site-packages\keras\utils\traceback_utils.py", line 70, in error_handler
    raise e.with_traceback(filtered_tb) from None
  File "C:\Users\Gourav\AppData\Local\Programs\Python\Python310\lib\site-packages\tensorflow\python\eager\execute.py", line 54, in quick_execute
    tensors = pywrap_tfe.TFE_Py_Execute(ctx._handle, device_name, op_name,
tensorflow.python.framework.errors_impl.UnknownError: Graph execution error:

2 root error(s) found.
  (0) UNKNOWN:  FileNotFoundError: [Errno 2] No such file or directory: 'artifacts\\data_ingestion\\kidney-ct-scan-image\\CT-KIDNEY-DATASET-Normal-Cyst-Tumor-Stone\\CT-KIDNEY-DATASET-Normal-Cyst-Tumor-Stone\\Cyst\\Cyst- (819).jpg'
Traceback (most recent call last):

  File "C:\Users\Gourav\AppData\Local\Programs\Python\Python310\lib\site-packages\tensorflow\python\ops\script_ops.py", line 271, in __call__
    ret = func(*args)

  File "C:\Users\Gourav\AppData\Local\Programs\Python\Python310\lib\site-packages\tensorflow\python\autograph\impl\api.py", line 642, in wrapper
    return func(*args, **kwargs)

  File "C:\Users\Gourav\AppData\Local\Programs\Python\Python310\lib\site-packages\tensorflow\python\data\ops\dataset_ops.py", line 1035, in generator_py_func
    values = next(generator_state.get_iterator(iterator_id))

  File "C:\Users\Gourav\AppData\Local\Programs\Python\Python310\lib\site-packages\keras\engine\data_adapter.py", line 903, in wrapped_generator
    for data in generator_fn():

  File "C:\Users\Gourav\AppData\Local\Programs\Python\Python310\lib\site-packages\keras\engine\data_adapter.py", line 1050, in generator_fn
    yield x[i]

  File "C:\Users\Gourav\AppData\Local\Programs\Python\Python310\lib\site-packages\keras\preprocessing\image.py", line 116, in __getitem__
    return self._get_batches_of_transformed_samples(index_array)

  File "C:\Users\Gourav\AppData\Local\Programs\Python\Python310\lib\site-packages\keras\preprocessing\image.py", line 370, in _get_batches_of_transformed_samples
    img = image_utils.load_img(

  File "C:\Users\Gourav\AppData\Local\Programs\Python\Python310\lib\site-packages\keras\utils\image_utils.py", line 422, in load_img
    with open(path, "rb") as f:

FileNotFoundError: [Errno 2] No such file or directory: 'artifacts\\data_ingestion\\kidney-ct-scan-image\\CT-KIDNEY-DATASET-Normal-Cyst-Tumor-Stone\\CT-KIDNEY-DATASET-Normal-Cyst-Tumor-Stone\\Cyst\\Cyst- (819).jpg'


	 [[{{node PyFunc}}]]
	 [[IteratorGetNext]]
	 [[IteratorGetNext/_2]]
  (1) UNKNOWN:  FileNotFoundError: [Errno 2] No such file or directory: 'artifacts\\data_ingestion\\kidney-ct-scan-image\\CT-KIDNEY-DATASET-Normal-Cyst-Tumor-Stone\\CT-KIDNEY-DATASET-Normal-Cyst-Tumor-Stone\\Cyst\\Cyst- (819).jpg'
Traceback (most recent call last):

  File "C:\Users\Gourav\AppData\Local\Programs\Python\Python310\lib\site-packages\tensorflow\python\ops\script_ops.py", line 271, in __call__
    ret = func(*args)

  File "C:\Users\Gourav\AppData\Local\Programs\Python\Python310\lib\site-packages\tensorflow\python\autograph\impl\api.py", line 642, in wrapper
    return func(*args, **kwargs)

  File "C:\Users\Gourav\AppData\Local\Programs\Python\Python310\lib\site-packages\tensorflow\python\data\ops\dataset_ops.py", line 1035, in generator_py_func
    values = next(generator_state.get_iterator(iterator_id))

  File "C:\Users\Gourav\AppData\Local\Programs\Python\Python310\lib\site-packages\keras\engine\data_adapter.py", line 903, in wrapped_generator
    for data in generator_fn():

  File "C:\Users\Gourav\AppData\Local\Programs\Python\Python310\lib\site-packages\keras\engine\data_adapter.py", line 1050, in generator_fn
    yield x[i]

  File "C:\Users\Gourav\AppData\Local\Programs\Python\Python310\lib\site-packages\keras\preprocessing\image.py", line 116, in __getitem__
    return self._get_batches_of_transformed_samples(index_array)

  File "C:\Users\Gourav\AppData\Local\Programs\Python\Python310\lib\site-packages\keras\preprocessing\image.py", line 370, in _get_batches_of_transformed_samples
    img = image_utils.load_img(

  File "C:\Users\Gourav\AppData\Local\Programs\Python\Python310\lib\site-packages\keras\utils\image_utils.py", line 422, in load_img
    with open(path, "rb") as f:

FileNotFoundError: [Errno 2] No such file or directory: 'artifacts\\data_ingestion\\kidney-ct-scan-image\\CT-KIDNEY-DATASET-Normal-Cyst-Tumor-Stone\\CT-KIDNEY-DATASET-Normal-Cyst-Tumor-Stone\\Cyst\\Cyst- (819).jpg'


	 [[{{node PyFunc}}]]
	 [[IteratorGetNext]]
0 successful operations.
0 derived errors ignored. [Op:__inference_train_function_1909]
[2025-05-24 19:07:55,386: INFO: main: >>>>>>>>>>>>>> Stage Model Preparation started <<<<<<<<<<<<<<]
[2025-05-24 19:07:55,386: INFO: common: yaml file: config\config.yaml loaded successfully]
[2025-05-24 19:07:55,386: INFO: common: yaml file: params.yaml loaded successfully]
[2025-05-24 19:07:55,386: INFO: common: created directory at: artifacts]
[2025-05-24 19:07:55,386: INFO: common: created directory at: artifacts/prepare_base_model]
[2025-05-24 19:07:56,261: WARNING: saving_utils: Compiled the loaded model, but the compiled metrics have yet to be built. `model.compile_metrics` will be empty until you train or evaluate the model.]
[2025-05-24 19:07:56,556: INFO: main: >>>>>>>>>>>> Stage Model Preparation COMPLETED <<<<<<<<<

X=========================================================X]
[2025-05-24 19:07:56,556: INFO: main: >>>>>>>>>>>>>> Stage Model Training started <<<<<<<<<<<<<<]
[2025-05-24 19:07:56,556: INFO: common: yaml file: config\config.yaml loaded successfully]
[2025-05-24 19:07:56,572: INFO: common: yaml file: params.yaml loaded successfully]
[2025-05-24 19:07:56,572: INFO: common: created directory at: artifacts]
[2025-05-24 19:07:56,572: INFO: common: created directory at: artifacts\training]
[2025-05-24 19:41:59,964: INFO: main: >>>>>>>>>>>> Stage Model Training COMPLETED <<<<<<<<<

X=========================================================X]
